2018-06-19 21:49:38,231 mothra ERROR Error processing bugs
Traceback (most recent call last):
  File "mothra.py", line 43, in main
    svn_cli.svn_checkout_or_update(settings.DATA_DIR, settings.SVN_URL)
  File "D:\Dev\integration\tools\mothra\trunk\svn_cli.py", line 21, in svn_checkout_or_update
    svn_update(local_path)
  File "D:\Dev\integration\tools\mothra\trunk\svn_cli.py", line 33, in svn_update
    '--password', settings.SVN_PASSWORD, 'update', local_path, '--force'])
  File "C:\Apps\Python\Python36-32\lib\subprocess.py", line 336, in check_output
    **kwargs).stdout
  File "C:\Apps\Python\Python36-32\lib\subprocess.py", line 403, in run
    with Popen(*popenargs, **kwargs) as process:
  File "C:\Apps\Python\Python36-32\lib\subprocess.py", line 709, in __init__
    restore_signals, start_new_session)
  File "C:\Apps\Python\Python36-32\lib\subprocess.py", line 997, in _execute_child
    startupinfo)
FileNotFoundError: [WinError 2] The system cannot find the file specified
